---
title: aiomysql
date: 2023-11-26 21:26 -0800
categories: [database, mysql]
tags: [mysql, aiomysql]
---

## Problem statement

Our company uses `sqlalchemy + aiomysql`, and sometimes we see blow error. Not sure what happens

```
  File "sqlalchemy/pool/base.py", line 894, in _checkout
              fairy = _ConnectionRecord.checkout(pool)
  File "sqlalchemy/pool/base.py", line 497, in checkout
              with util.safe_reraise():
  File "sqlalchemy/util/langhelpers.py", line 70, in __exit__
                  compat.raise_(
  File "sqlalchemy/util/compat.py", line 211, in raise_
              raise exception
  File "sqlalchemy/pool/base.py", line 495, in checkout
              dbapi_connection = rec.get_connection()
  File "sqlalchemy/pool/base.py", line 659, in get_connection
              self.__connect()
  File "sqlalchemy/pool/base.py", line 690, in __connect
              with util.safe_reraise():
  File "sqlalchemy/util/langhelpers.py", line 70, in __exit__
                  compat.raise_(
  File "sqlalchemy/util/compat.py", line 211, in raise_
              raise exception
  File "sqlalchemy/pool/base.py", line 686, in __connect
              self.dbapi_connection = connection = pool._invoke_creator(self)
  File "sqlalchemy/engine/create.py", line 574, in connect
              return dialect.connect(*cargs, **cparams)
  File "sqlalchemy/engine/default.py", line 598, in connect
          return self.dbapi.connect(*cargs, **cparams)
  File "sqlalchemy/dialects/mysql/aiomysql.py", line 254, in connect
                  await_only(self.aiomysql.connect(*arg, **kw)),
  File "sqlalchemy/util/_concurrency_py3k.py", line 68, in await_only
      return current.driver.switch(awaitable)
  File "sqlalchemy/util/_concurrency_py3k.py", line 121, in greenlet_spawn
                  value = await result
  File "ddtrace/contrib/aiomysql/patch.py", line 41, in patched_connect
      conn = await connect_func(*args, **kwargs)
  File "aiomysql/connection.py", line 75, in _connect
      await conn._connect()
  File "aiomysql/connection.py", line 540, in _connect
              await self._request_authentication()
  File "aiomysql/connection.py", line 844, in _request_authentication
          auth_packet = await self._read_packet()
  File "aiomysql/connection.py", line 629, in _read_packet
                  raise InternalError(
sqlalchemy.exc.InternalError: (pymysql.err.InternalError) Packet sequence number wrong - got 1 expected 2
```

## Mysql packet

https://dev.mysql.com/doc/dev/mysql-server/latest/page_protocol_basic_packets.html
